DK Firebase Admin initialisé avec succès.
SDK Firebase Admin initialisé avec succès.
Watching for file changes with StatReloader
Performing system checks...

System check identified no issues (0 silenced).
July 25, 2025 - 21:37:39
Django version 5.2.4, using settings 'immobenin_backend.settings'
Starting development server at http://127.0.0.1:8000/
Quit the server with CONTROL-C.

WARNING: This is a development server. Do not use it in a production setting. Use a production WSGI or ASGI server instead.
For more information on production servers see: https://docs.djangoproject.com/en/5.2/howto/deployment/
[25/Jul/2025 21:37:49] "OPTIONS /api/firebase-login/ HTTP/1.1" 200 0
[25/Jul/2025 21:37:49] "OPTIONS /api/firebase-login/ HTTP/1.1" 200 0
[25/Jul/2025 21:37:50] "POST /api/firebase-login/ HTTP/1.1" 200 137
Traceback (most recent call last):
  File "/home/alexis/Bureau/Alexis_portfolio/immo-benin/backend/authentication/views.py", line 35, in post
    user = User.objects.get(firebase_uid=uid)
           ^^^^^^^^^^^^^^^^^^^^^^^^^^^^^^^^^^
  File "/home/alexis/.local/lib/python3.12/site-packages/django/db/models/manager.py", line 87, in manager_method
    return getattr(self.get_queryset(), name)(*args, **kwargs)
           ^^^^^^^^^^^^^^^^^^^^^^^^^^^^^^^^^^^^^^^^^^^^^^^^^^^
  File "/home/alexis/.local/lib/python3.12/site-packages/django/db/models/query.py", line 633, in get
    raise self.model.DoesNotExist(
authentication.models.CustomUser.DoesNotExist: CustomUser matching query does not exist.

During handling of the above exception, another exception occurred:

Traceback (most recent call last):
  File "/home/alexis/Bureau/Alexis_portfolio/immo-benin/backend/authentication/views.py", line 39, in post
    user = User.objects.get(email=email)
           ^^^^^^^^^^^^^^^^^^^^^^^^^^^^^
  File "/home/alexis/.local/lib/python3.12/site-packages/django/db/models/manager.py", line 87, in manager_method
    return getattr(self.get_queryset(), name)(*args, **kwargs)
           ^^^^^^^^^^^^^^^^^^^^^^^^^^^^^^^^^^^^^^^^^^^^^^^^^^^
  File "/home/alexis/.local/lib/python3.12/site-packages/django/db/models/query.py", line 633, in get
    raise self.model.DoesNotExist(
authentication.models.CustomUser.DoesNotExist: CustomUser matching query does not exist.

During handling of the above exception, another exception occurred:

Traceback (most recent call last):
  File "/home/alexis/.local/lib/python3.12/site-packages/django/db/backends/utils.py", line 105, in _execute
    return self.cursor.execute(sql, params)
           ^^^^^^^^^^^^^^^^^^^^^^^^^^^^^^^^
  File "/home/alexis/.local/lib/python3.12/site-packages/django/db/backends/sqlite3/base.py", line 360, in execute
    return super().execute(query, params)
           ^^^^^^^^^^^^^^^^^^^^^^^^^^^^^^
sqlite3.IntegrityError: UNIQUE constraint failed: authentication_customuser.firebase_uid

The above exception was the direct cause of the following exception:

Traceback (most recent call last):
  File "/home/alexis/Bureau/Alexis_portfolio/immo-benin/backend/authentication/views.py", line 47, in post
    user = User.objects.create(
           ^^^^^^^^^^^^^^^^^^^^
  File "/home/alexis/.local/lib/python3.12/site-packages/django/db/models/manager.py", line 87, in manager_method
    return getattr(self.get_queryset(), name)(*args, **kwargs)
           ^^^^^^^^^^^^^^^^^^^^^^^^^^^^^^^^^^^^^^^^^^^^^^^^^^^
  File "/home/alexis/.local/lib/python3.12/site-packages/django/db/models/query.py", line 663, in create
    obj.save(force_insert=True, using=self.db)
  File "/home/alexis/.local/lib/python3.12/site-packages/django/contrib/auth/base_user.py", line 65, in save
    super().save(*args, **kwargs)
  File "/home/alexis/.local/lib/python3.12/site-packages/django/db/models/base.py", line 902, in save
    self.save_base(
  File "/home/alexis/.local/lib/python3.12/site-packages/django/db/models/base.py", line 1008, in save_base
    updated = self._save_table(
              ^^^^^^^^^^^^^^^^^
  File "/home/alexis/.local/lib/python3.12/site-packages/django/db/models/base.py", line 1169, in _save_table
    results = self._do_insert(
              ^^^^^^^^^^^^^^^^
  File "/home/alexis/.local/lib/python3.12/site-packages/django/db/models/base.py", line 1210, in _do_insert
    return manager._insert(
           ^^^^^^^^^^^^^^^^
  File "/home/alexis/.local/lib/python3.12/site-packages/django/db/models/manager.py", line 87, in manager_method
    return getattr(self.get_queryset(), name)(*args, **kwargs)
           ^^^^^^^^^^^^^^^^^^^^^^^^^^^^^^^^^^^^^^^^^^^^^^^^^^^
  File "/home/alexis/.local/lib/python3.12/site-packages/django/db/models/query.py", line 1868, in _insert
    return query.get_compiler(using=using).execute_sql(returning_fields)
           ^^^^^^^^^^^^^^^^^^^^^^^^^^^^^^^^^^^^^^^^^^^^^^^^^^^^^^^^^^^^^
  File "/home/alexis/.local/lib/python3.12/site-packages/django/db/models/sql/compiler.py", line 1882, in execute_sql
    cursor.execute(sql, params)
  File "/home/alexis/.local/lib/python3.12/site-packages/django/db/backends/utils.py", line 122, in execute
    return super().execute(sql, params)
           ^^^^^^^^^^^^^^^^^^^^^^^^^^^^
  File "/home/alexis/.local/lib/python3.12/site-packages/django/db/backends/utils.py", line 79, in execute
    return self._execute_with_wrappers(
           ^^^^^^^^^^^^^^^^^^^^^^^^^^^^
  File "/home/alexis/.local/lib/python3.12/site-packages/django/db/backends/utils.py", line 92, in _execute_with_wrappers
    return executor(sql, params, many, context)
           ^^^^^^^^^^^^^^^^^^^^^^^^^^^^^^^^^^^^
  File "/home/alexis/.local/lib/python3.12/site-packages/django/db/backends/utils.py", line 100, in _execute
    with self.db.wrap_database_errors:
  File "/home/alexis/.local/lib/python3.12/site-packages/django/db/utils.py", line 91, in __exit__
    raise dj_exc_value.with_traceback(traceback) from exc_value
  File "/home/alexis/.local/lib/python3.12/site-packages/django/db/backends/utils.py", line 105, in _execute
    return self.cursor.execute(sql, params)
           ^^^^^^^^^^^^^^^^^^^^^^^^^^^^^^^^
  File "/home/alexis/.local/lib/python3.12/site-packages/django/db/backends/sqlite3/base.py", line 360, in execute
    return super().execute(query, params)
           ^^^^^^^^^^^^^^^^^^^^^^^^^^^^^^
django.db.utils.IntegrityError: UNIQUE constraint failed: authentication_customuser.firebase_uid
Erreur lors de la connexion Firebase: UNIQUE constraint failed: authentication_customuser.firebase_uid
Internal Server Error: /api/firebase-login/
[25/Jul/2025 21:37:50] "POST /api/firebase-login/ HTTP/1.1" 500 99
[25/Jul/2025 21:37:57] "POST /api/firebase-login/ HTTP/1.1" 200 147
Traceback (most recent call last):
  File "/home/alexis/Bureau/Alexis_portfolio/immo-benin/backend/authentication/views.py", line 35, in post
    user = User.objects.get(firebase_uid=uid)
           ^^^^^^^^^^^^^^^^^^^^^^^^^^^^^^^^^^
  File "/home/alexis/.local/lib/python3.12/site-packages/django/db/models/manager.py", line 87, in manager_method
    return getattr(self.get_queryset(), name)(*args, **kwargs)
           ^^^^^^^^^^^^^^^^^^^^^^^^^^^^^^^^^^^^^^^^^^^^^^^^^^^
  File "/home/alexis/.local/lib/python3.12/site-packages/django/db/models/query.py", line 633, in get
    raise self.model.DoesNotExist(
authentication.models.CustomUser.DoesNotExist: CustomUser matching query does not exist.

During handling of the above exception, another exception occurred:

Traceback (most recent call last):
  File "/home/alexis/Bureau/Alexis_portfolio/immo-benin/backend/authentication/views.py", line 39, in post
    user = User.objects.get(email=email)
           ^^^^^^^^^^^^^^^^^^^^^^^^^^^^^
  File "/home/alexis/.local/lib/python3.12/site-packages/django/db/models/manager.py", line 87, in manager_method
    return getattr(self.get_queryset(), name)(*args, **kwargs)
           ^^^^^^^^^^^^^^^^^^^^^^^^^^^^^^^^^^^^^^^^^^^^^^^^^^^
  File "/home/alexis/.local/lib/python3.12/site-packages/django/db/models/query.py", line 633, in get
    raise self.model.DoesNotExist(
authentication.models.CustomUser.DoesNotExist: CustomUser matching query does not exist.

During handling of the above exception, another exception occurred:

Traceback (most recent call last):
  File "/home/alexis/.local/lib/python3.12/site-packages/django/db/backends/utils.py", line 105, in _execute
    return self.cursor.execute(sql, params)
           ^^^^^^^^^^^^^^^^^^^^^^^^^^^^^^^^
  File "/home/alexis/.local/lib/python3.12/site-packages/django/db/backends/sqlite3/base.py", line 360, in execute
    return super().execute(query, params)
           ^^^^^^^^^^^^^^^^^^^^^^^^^^^^^^
sqlite3.IntegrityError: UNIQUE constraint failed: authentication_customuser.firebase_uid

The above exception was the direct cause of the following exception:

Traceback (most recent call last):
  File "/home/alexis/Bureau/Alexis_portfolio/immo-benin/backend/authentication/views.py", line 47, in post
    user = User.objects.create(
           ^^^^^^^^^^^^^^^^^^^^
  File "/home/alexis/.local/lib/python3.12/site-packages/django/db/models/manager.py", line 87, in manager_method
    return getattr(self.get_queryset(), name)(*args, **kwargs)
           ^^^^^^^^^^^^^^^^^^^^^^^^^^^^^^^^^^^^^^^^^^^^^^^^^^^
  File "/home/alexis/.local/lib/python3.12/site-packages/django/db/models/query.py", line 663, in create
    obj.save(force_insert=True, using=self.db)
  File "/home/alexis/.local/lib/python3.12/site-packages/django/contrib/auth/base_user.py", line 65, in save
    super().save(*args, **kwargs)
  File "/home/alexis/.local/lib/python3.12/site-packages/django/db/models/base.py", line 902, in save
    self.save_base(
  File "/home/alexis/.local/lib/python3.12/site-packages/django/db/models/base.py", line 1008, in save_base
    updated = self._save_table(
              ^^^^^^^^^^^^^^^^^
  File "/home/alexis/.local/lib/python3.12/site-packages/django/db/models/base.py", line 1169, in _save_table
    results = self._do_insert(
              ^^^^^^^^^^^^^^^^
  File "/home/alexis/.local/lib/python3.12/site-packages/django/db/models/base.py", line 1210, in _do_insert
    return manager._insert(
           ^^^^^^^^^^^^^^^^
  File "/home/alexis/.local/lib/python3.12/site-packages/django/db/models/manager.py", line 87, in manager_method
    return getattr(self.get_queryset(), name)(*args, **kwargs)
           ^^^^^^^^^^^^^^^^^^^^^^^^^^^^^^^^^^^^^^^^^^^^^^^^^^^
  File "/home/alexis/.local/lib/python3.12/site-packages/django/db/models/query.py", line 1868, in _insert
    return query.get_compiler(using=using).execute_sql(returning_fields)
           ^^^^^^^^^^^^^^^^^^^^^^^^^^^^^^^^^^^^^^^^^^^^^^^^^^^^^^^^^^^^^
  File "/home/alexis/.local/lib/python3.12/site-packages/django/db/models/sql/compiler.py", line 1882, in execute_sql
    cursor.execute(sql, params)
  File "/home/alexis/.local/lib/python3.12/site-packages/django/db/backends/utils.py", line 122, in execute
    return super().execute(sql, params)
           ^^^^^^^^^^^^^^^^^^^^^^^^^^^^
  File "/home/alexis/.local/lib/python3.12/site-packages/django/db/backends/utils.py", line 79, in execute
    return self._execute_with_wrappers(
           ^^^^^^^^^^^^^^^^^^^^^^^^^^^^
  File "/home/alexis/.local/lib/python3.12/site-packages/django/db/backends/utils.py", line 92, in _execute_with_wrappers
    return executor(sql, params, many, context)
           ^^^^^^^^^^^^^^^^^^^^^^^^^^^^^^^^^^^^
  File "/home/alexis/.local/lib/python3.12/site-packages/django/db/backends/utils.py", line 100, in _execute
    with self.db.wrap_database_errors:
  File "/home/alexis/.local/lib/python3.12/site-packages/django/db/utils.py", line 91, in __exit__
    raise dj_exc_value.with_traceback(traceback) from exc_value
  File "/home/alexis/.local/lib/python3.12/site-packages/django/db/backends/utils.py", line 105, in _execute
    return self.cursor.execute(sql, params)
           ^^^^^^^^^^^^^^^^^^^^^^^^^^^^^^^^
  File "/home/alexis/.local/lib/python3.12/site-packages/django/db/backends/sqlite3/base.py", line 360, in execute
    return super().execute(query, params)
           ^^^^^^^^^^^^^^^^^^^^^^^^^^^^^^
django.db.utils.IntegrityError: UNIQUE constraint failed: authentication_customuser.firebase_uid
Erreur lors de la connexion Firebase: UNIQUE constraint failed: authentication_customuser.firebase_uid
Internal Server Error: /api/firebase-login/
[25/Jul/2025 21:37:57] "POST /api/firebase-login/ HTTP/1.1" 500 99



